<?xml version="1.0" encoding="utf-8"?>
<robot name="franka">
  <link name="base_link"/>
  <joint name="base_link_robot" type="fixed">
    <origin xyz="0 0 0" rpy="0 0 0"/>
    <parent link="base_link"/>
    <child link="panda_link0"/>
  </joint>

  <link name="panda_link0"/>
  <link name="panda_link1"/>
  <joint name="panda_joint1" type="revolute">
    <origin xyz="0 0 0.333" rpy="0 0 0"/>
    <parent link="panda_link0"/>
    <child link="panda_link1"/>
    <axis xyz="0 0 1"/>
    <limit effort="87" lower="-2.8973" upper="2.8973" velocity="2.1750"/>
  </joint>

  <link name="panda_link2"/>
  <joint name="panda_joint2" type="revolute">
    <origin xyz="0 0 0" rpy="-1.57079632679 0 0"/>
    <parent link="panda_link1"/>
    <child link="panda_link2"/>
    <axis xyz="0 0 1"/>
    <limit effort="87" lower="-1.7628" upper="1.7628" velocity="2.1750"/>
  </joint>

  <link name="panda_link3"/>
  <joint name="panda_joint3" type="revolute">
    <origin xyz="0 -0.316 0" rpy="1.57079632679 0 0"/>
    <parent link="panda_link2"/>
    <child link="panda_link3"/>
    <axis xyz="0 0 1"/>
    <limit effort="87" lower="-2.8973" upper="2.8973" velocity="2.1750"/>
  </joint>

  <link name="panda_link4"/>
  <joint name="panda_joint4" type="revolute">
    <origin xyz="0.0825 0 0" rpy="1.57079632679 0 0"/>
    <parent link="panda_link3"/>
    <child link="panda_link4"/>
    <axis xyz="0 0 1"/>
    <limit effort="87" lower="-3.0718" upper="-0.0698" velocity="2.1750"/>
  </joint>

  <link name="panda_link5"/>
  <joint name="panda_joint5" type="revolute">
    <origin xyz="-0.0825 0.384 0" rpy="-1.57079632679 0 0"/>
    <parent link="panda_link4"/>
    <child link="panda_link5"/>
    <axis xyz="0 0 1"/>
    <limit effort="12" lower="-2.8973" upper="2.8973" velocity="2.6100"/>
  </joint>

  <link name="panda_link6"/>
  <joint name="panda_joint6" type="revolute">
    <origin xyz="0 0 0" rpy="1.57079632679 0 0"/>
    <parent link="panda_link5"/>
    <child link="panda_link6"/>
    <axis xyz="0 0 1"/>
    <limit effort="12" lower="-0.0175" upper="3.7525" velocity="2.6100"/>
  </joint>

  <link name="panda_link7"/>
  <joint name="panda_joint7" type="revolute">
    <origin xyz="0.088 0 0" rpy="1.57079632679 0 0"/>
    <parent link="panda_link6"/>
    <child link="panda_link7"/>
    <axis xyz="0 0 1"/>
    <limit effort="12" lower="-2.8973" upper="2.8973" velocity="2.6100"/>
  </joint>

  <link name="panda_link8"/>
  <joint name="panda_joint8" type="fixed">
    <origin xyz="0 0 0.107" rpy="0 0 0"/>
    <parent link="panda_link7"/>
    <child link="panda_link8"/>
  </joint>

  <link name="panda_hand"/>
  <joint name="panda_hand_joint" type="fixed">
    <origin xyz="0 0 0" rpy="0 0 -0.785398163397"/>
    <parent link="panda_link8"/>
    <child link="panda_hand"/>
  </joint>
</robot>
